<?xml version="1.0"?>
<!-- created with Phobos 1.0.1 "Capricious Choutengan" -->
  <robot name="Paucibot">
    <material name="wood">
      <color rgba="0.5 0.3 0.13 1.0"/>
    </material>
    <material name="tire">
      <color rgba="0.1 0.1 0.1 1.0" />
    </material>
    <material name="white">
      <color rgba="1.0 1.0 1.0 0.9" />
    </material>
    <material name="brack" >
      <color rgba="0.8 0.4 0.11 1.0" />
    </material>

    <gazebo reference="BaseLink">
      <material>Gazebo/Orange</material>
    </gazebo>
    <gazebo reference="wheel1_link">
      <material>Gazebo/Black</material>
    </gazebo>
    <gazebo reference="wheel2_link">
      <material>Gazebo/Black</material>
    </gazebo>
    <gazebo reference="Holder1_link">
      <material>Gazebo/Black</material>
    </gazebo>
    <gazebo reference="Holder2_link">
      <material>Gazebo/Black</material>
    </gazebo>
    <gazebo reference="Motor1_link">
      <material>Gazebo/Black</material>
    </gazebo>
    <gazebo reference="Motor2_link">
      <material>Gazebo/Black</material>
    </gazebo>
    <gazebo reference="Pillar1_link">
      <material>Gazebo/Black</material>
    </gazebo>
    <gazebo reference="Pillar2_link">
      <material>Gazebo/Black</material>
    </gazebo>
    <gazebo reference="Pillar3_link">
      <material>Gazebo/Black</material>
    </gazebo>
    <gazebo reference="UpperLink">
      <material>Gazebo/Black</material>
    </gazebo>


    <link name="BaseLink">
      <inertial>
        <origin xyz="0 0 -0.00275" rpy="0 0 0"/>
        <mass value="0.07"/>
        <inertia ixx="0.0001" ixy="0" ixz="0" iyy="0.0001" iyz="0" izz="0.0002"/>
      </inertial>
      <visual name="lower_disc">
        <origin xyz="0 0 0" rpy="0 0 0"/>
        <geometry>
          <mesh filename="package://paucibot/meshes/stl/Circle.004.stl" scale="0.075 0.075 0.06329"/>
        </geometry>
        <material name="wood"/>
      </visual>
      <collision name="lower_disc">
        <origin xyz="0 0 -0.00275" rpy="0 0 0"/>
        <geometry>
          <cylinder radius="0.075" length="0.0055"/>
        </geometry>
      </collision>
    </link>

    <link name="Holder1_link">
      <inertial>
        <origin xyz="0 0 0" rpy="0 0 0"/>
        <mass value="0.03"/>
        <inertia ixx="0.001" ixy="0" ixz="0" iyy="0.001" iyz="0" izz="0.001"/>
      </inertial>
      <visual name="Holder2">
        <origin xyz="0 0 0" rpy="0 0 0"/>
        <geometry>
          <mesh filename="package://paucibot/meshes/stl/Cube.010.stl" scale="0.95238 0.7619 0.03429"/>
        </geometry>
        <material name="brack"/>
      </visual>
      <collision name="Holder2">
        <origin xyz="0.00045 0 0.01455" rpy="0 0 0"/>
        <geometry>
          <box size="0.0509 0.04 0.0309"/>
        </geometry>
      </collision>
    </link>

    <link name="Holder2_link">
      <inertial>
        <origin xyz="0 0 0" rpy="0 0 0"/>
        <mass value="0.03"/>
        <inertia ixx="0.001" ixy="0" ixz="0" iyy="0.001" iyz="0" izz="0.001"/>
      </inertial>
      <visual name="Holder1">
        <origin xyz="0 0 0" rpy="0 0 0"/>
        <geometry>
          <mesh filename="package://paucibot/meshes/stl/Cube.009.stl" scale="0.95238 0.7619 0.03429"/>
        </geometry>
        <material name="brack"/>
      </visual>
      <collision name="Holder1">
        <origin xyz="0.00045 0 0.01455" rpy="0 0 0"/>
        <geometry>
          <box size="0.0509 0.04 0.0309"/>
        </geometry>
      </collision>
    </link>

    <link name="Motor1_link">
      <inertial>
        <origin xyz="0 0 -0.02034" rpy="0 0 0"/>
        <mass value="0.225"/>
        <inertia ixx="7e-05" ixy="0" ixz="0" iyy="3e-05" iyz="0" izz="2e-05"/>
      </inertial>
      <visual name="Motor1">
        <origin xyz="0 0 0" rpy="0 0 0"/>
        <geometry>
          <mesh filename="package://paucibot/meshes/stl/Cylinder.stl" scale="1.0 1.0 1.0"/>
        </geometry>
        <material name="white" />
      </visual>
      <collision name="Motor1">
        <origin xyz="0 0 -0.02034" rpy="0 0 0"/>
        <geometry>
          <cylinder radius="0.018" length="0.06216"/>
        </geometry>
      </collision>
    </link>

    <link name="Motor2_link">
      <inertial>
        <origin xyz="0 0 -0.02027" rpy="0 0 0"/>
        <mass value="0.225"/>
        <inertia ixx="7e-05" ixy="0" ixz="0" iyy="3e-05" iyz="0" izz="2e-05"/>
      </inertial>
      <visual name="Motor2">
        <origin xyz="0 0 0" rpy="0 0 0"/>
        <geometry>
          <mesh filename="package://paucibot/meshes/stl/Cylinder.001.stl" scale="1.0 1.0 1.0"/>
        </geometry>
        <material name="white" />
      </visual>
      <collision name="Motor2">
        <origin xyz="0 0 -0.02027" rpy="0 0 0"/>
        <geometry>
          <cylinder radius="0.018" length="0.06262"/>
        </geometry>
      </collision>
    </link>

    <link name="Pillar1_link">
      <inertial>
        <origin xyz="0 0 0" rpy="0 0 0"/>
        <mass value="0.001"/>
        <inertia ixx="2e-05" ixy="0" ixz="0" iyy="2e-05" iyz="0" izz="2e-05"/>
      </inertial>
      <visual name="Pillar1">
        <origin xyz="0 0 0" rpy="0 0 0"/>
        <geometry>
          <box size="0.0085 0.0055 0.0525"/>
        </geometry>
        <material name="wood"/>
      </visual>
      <collision name="Pillar1">
        <origin xyz="0 0 0" rpy="0 0 0"/>
        <geometry>
          <box size="0.0085 0.0055 0.0525"/>
        </geometry>
      </collision>
    </link>

    <link name="Pillar2_link">
      <inertial>
        <origin xyz="0 0 0" rpy="0 0 0"/>
        <mass value="0.001"/>
        <inertia ixx="2e-05" ixy="0" ixz="0" iyy="2e-05" iyz="0" izz="2e-05"/>
      </inertial>
      <visual name="Pillar2">
        <origin xyz="0 0 0" rpy="0 0 0"/>
        <geometry>
          <box size="0.0085 0.0055 0.0525"/>
        </geometry>
        <material name="wood"/>
      </visual>
      <collision name="Pillar2">
        <origin xyz="0 0 0" rpy="0 0 0"/>
        <geometry>
          <box size="0.0085 0.0055 0.0525"/>
        </geometry>
      </collision>
    </link>

    <link name="Pillar3_link">
      <inertial>
        <origin xyz="0 0 0" rpy="0 0 0"/>
        <mass value="0.001"/>
        <inertia ixx="2e-05" ixy="0" ixz="0" iyy="2e-05" iyz="0" izz="2e-05"/>
      </inertial>
      <visual name="Pillar3">
        <origin xyz="0 0 0" rpy="0 0 0"/>
        <geometry>
          <box size="0.0085 0.0055 0.0525"/>
        </geometry>
        <material name="wood"/>
      </visual>
      <collision name="Pillar3">
        <origin xyz="0 0 0" rpy="0 0 0"/>
        <geometry>
          <box size="0.0085 0.0055 0.0525"/>
        </geometry>
      </collision>
    </link>

    <link name="UpperLink">
      <inertial>
        <origin xyz="0 0 -0.00275" rpy="0 0 0"/>
        <mass value="0.07"/>
        <inertia ixx="0.0001" ixy="0" ixz="0" iyy="0.0001" iyz="0" izz="0.0002"/>
      </inertial>
      <visual name="upper_disc">
        <origin xyz="0 0 0" rpy="0 0 0"/>
        <geometry>
          <mesh filename="package://paucibot/meshes/stl/Circle.003.stl" scale="0.075 0.075 0.06329"/>
        </geometry>
        <material name="wood"/>
      </visual>
      <collision name="upper_disc">
        <origin xyz="0 0 -0.00275" rpy="0 0 0"/>
        <geometry>
          <cylinder radius="0.075" length="0.0055"/>
        </geometry>
      </collision>
    </link>

    <link name="wheel1_link">
      <inertial>
        <origin xyz="0 0 0" rpy="0 0 0"/>
        <mass value="0.13"/>
        <inertia ixx="4e-05" ixy="0" ixz="0" iyy="7e-05" iyz="0" izz="0.00117"/>
      </inertial>
      <visual name="Wheel1">
        <origin xyz="0 0 0" rpy="0 0 0"/>
        <geometry>
          <mesh filename="package://paucibot/meshes/stl/Torus.stl" scale="0.81132 0.81132 1.89758"/>
        </geometry>
        <material name="tire" />
      </visual>
      <collision name="Wheel1">
        <origin xyz="0 0 0" rpy="0 0 0"/>
        <geometry>
          <cylinder radius="0.043" length="0.03798"/>
        </geometry>
      </collision>
    </link>

    <link name="wheel2_link">
      <inertial>
        <origin xyz="0 0 0" rpy="0 0 0"/>
        <mass value="0.13"/>
        <inertia ixx="4e-05" ixy="0" ixz="0" iyy="7e-05" iyz="0" izz="0.00117"/>
      </inertial>
      <visual name="Wheel2">
        <origin xyz="0 0 0" rpy="0 0 0"/>
        <geometry>
          <mesh filename="package://paucibot/meshes/stl/Torus.002.stl" scale="0.81132 0.81132 1.89758"/>
        </geometry>
        <material name="tire" />
      </visual>
      <collision name="Wheel2">
        <origin xyz="0 0 0" rpy="0 0 0"/>
        <geometry>
          <cylinder radius="0.043" length="0.03798"/>
        </geometry>
      </collision>
    </link>

    <joint name="Holder1_link" type="fixed">
      <origin xyz="0 0.075 -0.0323" rpy="1.5708 -1.5708 0"/>
      <parent link="BaseLink"/>
      <child link="Holder1_link"/>
    </joint>

    <joint name="Holder2_link" type="fixed">
      <origin xyz="0 -0.075 -0.0323" rpy="-1.5708 -1.5708 0"/>
      <parent link="BaseLink"/>
      <child link="Holder2_link"/>
    </joint>

    <joint name="Motor1_link" type="fixed">
      <origin xyz="0.002 0 0.0138" rpy="0 3.14159 0"/>
      <parent link="Holder1_link"/>
      <child link="Motor1_link"/>
    </joint>

    <joint name="Motor2_link" type="fixed">
      <origin xyz="0.002 0 0.0139" rpy="0 -3.14159 0"/>
      <parent link="Holder2_link"/>
      <child link="Motor2_link"/>
    </joint>

    <joint name="Pillar1_link" type="fixed">
      <origin xyz="-0.06127 0.03537 0.02625" rpy="0 0 -2.0944"/>
      <parent link="BaseLink"/>
      <child link="Pillar1_link"/>
    </joint>

    <joint name="Pillar2_link" type="fixed">
      <origin xyz="0 -0.07075 0.02625" rpy="0 0 0"/>
      <parent link="BaseLink"/>
      <child link="Pillar2_link"/>
    </joint>

    <joint name="Pillar3_link" type="fixed">
      <origin xyz="0.06127 0.03537 0.02625" rpy="0 0 2.0944"/>
      <parent link="BaseLink"/>
      <child link="Pillar3_link"/>
    </joint>

    <joint name="UpperLink" type="fixed">
      <origin xyz="0 0.07075 0.03175" rpy="0 0 0"/>
      <parent link="Pillar2_link"/>
      <child link="UpperLink"/>
    </joint>

    <joint name="wheel1_link" type="continuous">
      <origin xyz="-0.005 0 -0.0215" rpy="0 0 -1.5708"/>
      <parent link="Holder1_link"/>
      <child link="wheel1_link"/>
      <axis xyz="0 0 1.0"/>
      <limit effort="0.26" velocity="15.708"/>
    </joint>

    <joint name="wheel2_link" type="continuous">
      <origin xyz="0.007 0 0.0354" rpy="0 0 1.5708"/>
      <parent link="Motor2_link"/>
      <child link="wheel2_link"/>
      <axis xyz="0 0 1.0"/>
      <limit effort="0.26" velocity="15.708"/>
    </joint>

  </robot>
